
passed dict emned path ./dictionary_learning/dictionaries/pythia-70m-deduped/embed
Special tokens have been added in the vocabulary, make sure the associated word embeddings are fine-tuned or trained.
Traceback (most recent call last):
  File "/home/atticus/maheep/SAE_vs_DAS/main.py", line 296, in <module>
    train(DEVICE=args.device,
  File "/home/atticus/maheep/SAE_vs_DAS/main.py", line 40, in train
    epochs = epochs).to(DEVICE)
  File "/home/atticus/.local/lib/python3.10/site-packages/torch/nn/modules/module.py", line 1173, in to
    return self._apply(convert)
  File "/home/atticus/.local/lib/python3.10/site-packages/torch/nn/modules/module.py", line 779, in _apply
    module._apply(fn)
  File "/home/atticus/.local/lib/python3.10/site-packages/torch/nn/modules/module.py", line 779, in _apply
    module._apply(fn)
  File "/home/atticus/.local/lib/python3.10/site-packages/torch/nn/modules/module.py", line 779, in _apply
    module._apply(fn)
  File "/home/atticus/.local/lib/python3.10/site-packages/torch/nn/modules/module.py", line 804, in _apply
    param_applied = fn(param)
  File "/home/atticus/.local/lib/python3.10/site-packages/torch/nn/modules/module.py", line 1159, in convert
    return t.to(
RuntimeError: NVML_SUCCESS == DriverAPI::get()->nvmlInit_v2_() INTERNAL ASSERT FAILED at "../c10/cuda/CUDACachingAllocator.cpp":813, please report a bug to PyTorch.
Traceback (most recent call last):
  File "/home/atticus/maheep/SAE_vs_DAS/main.py", line 296, in <module>
    train(DEVICE=args.device,
  File "/home/atticus/maheep/SAE_vs_DAS/main.py", line 40, in train
    epochs = epochs).to(DEVICE)
  File "/home/atticus/.local/lib/python3.10/site-packages/torch/nn/modules/module.py", line 1173, in to
    return self._apply(convert)
  File "/home/atticus/.local/lib/python3.10/site-packages/torch/nn/modules/module.py", line 779, in _apply
    module._apply(fn)
  File "/home/atticus/.local/lib/python3.10/site-packages/torch/nn/modules/module.py", line 779, in _apply
    module._apply(fn)
  File "/home/atticus/.local/lib/python3.10/site-packages/torch/nn/modules/module.py", line 779, in _apply
    module._apply(fn)
  File "/home/atticus/.local/lib/python3.10/site-packages/torch/nn/modules/module.py", line 804, in _apply
    param_applied = fn(param)
  File "/home/atticus/.local/lib/python3.10/site-packages/torch/nn/modules/module.py", line 1159, in convert
    return t.to(
RuntimeError: NVML_SUCCESS == DriverAPI::get()->nvmlInit_v2_() INTERNAL ASSERT FAILED at "../c10/cuda/CUDACachingAllocator.cpp":813, please report a bug to PyTorch.